Workbook
Name Slicer_Months__Order_Date: #N/A
Name Slicer_Sources: #N/A
Name Slicer_Years__Order_Date: #N/A

Sheet Pivot
B4: Sum of Revenue | C4: Sum of Expenses | D4: Sum of Quantity | E4: Sum of Profit | F4: Count of Order_ID | G4: Average of Expense_Ratio_% | H4: Average of Profit_Margin_% | I4: Average of Return_Rate_% | J4: Average of Discount_%
B5: 401664.6 | C5: 257496.81 | D5: 2103 | E5: 144167.79 | F5: 500 | G5: 0.6444222 | H5: 0.3555782 | I5: 0.0478006 | J5: 0.05364
C8: Column Labels
C9: 2025 | H9: 2024 | M9: Total Sum of Revenue | N9: Total Sum of Expenses | O9: Total Sum of Quantity | P9: Total Sum of Profit | Q9: Total Count of Order_ID
B10: Row Labels | C10: Sum of Revenue | D10: Sum of Expenses | E10: Sum of Quantity | F10: Sum of Profit | G10: Count of Order_ID | H10: Sum of Revenue | I10: Sum of Expenses | J10: Sum of Quantity | K10: Sum of Profit | L10: Count of Order_ID
B11: Jan | C11: 13460.4 | D11: 8422.65 | E11: 84 | F11: 5037.75 | G11: 25 | H11: 18415.75 | I11: 12809.84 | J11: 88 | K11: 5605.91 | L11: 26 | M11: 31876.15 | N11: 21232.49 | O11: 172 | P11: 10643.66 | Q11: 51
B12: Feb | C12: 21868 | D12: 12701.69 | E12: 93 | F12: 9166.31 | G12: 27 | H12: 24586.8 | I12: 14518.01 | J12: 106 | K12: 10068.79 | L12: 26 | M12: 46454.8 | N12: 27219.7 | O12: 199 | P12: 19235.1 | Q12: 53
B13: Mar | C13: 14333.7 | D13: 8719.55 | E13: 59 | F13: 5614.15 | G13: 19 | H13: 10873 | I13: 6755.89 | J13: 99 | K13: 4117.11 | L13: 24 | M13: 25206.7 | N13: 15475.44 | O13: 158 | P13: 9731.26 | Q13: 43
B14: Apr | C14: 12644.9 | D14: 7314.99 | E14: 62 | F14: 5329.91 | G14: 20 | H14: 19689.05 | I14: 10632.34 | J14: 93 | K14: 9056.71 | L14: 20 | M14: 32333.95 | N14: 17947.33 | O14: 155 | P14: 14386.62 | Q14: 40
B15: May | C15: 15540.4 | D15: 10348.08 | E15: 89 | F15: 5192.32 | G15: 16 | H15: 13977.7 | I15: 9440.95 | J15: 79 | K15: 4536.75 | L15: 21 | M15: 29518.1 | N15: 19789.03 | O15: 168 | P15: 9729.07 | Q15: 37
B16: Jun | C16: 7325.6 | D16: 4342.19 | E16: 42 | F16: 2983.41 | G16: 11 | H16: 16213 | I16: 9461.8 | J16: 83 | K16: 6751.2 | L16: 21 | M16: 23538.6 | N16: 13803.99 | O16: 125 | P16: 9734.61 | Q16: 32
B17: Jul | C17: 25464.95 | D17: 16956.55 | E17: 101 | F17: 8508.4 | G17: 22 | H17: 17043.5 | I17: 10952.52 | J17: 94 | K17: 6090.98 | L17: 22 | M17: 42508.45 | N17: 27909.07 | O17: 195 | P17: 14599.38 | Q17: 44
B18: Aug | C18: 18369.3 | D18: 12636.02 | E18: 101 | F18: 5733.28 | G18: 19 | H18: 17356.8 | I18: 11629.96 | J18: 101 | K18: 5726.84 | L18: 25 | M18: 35726.1 | N18: 24265.98 | O18: 202 | P18: 11460.12 | Q18: 44
B19: Sep | C19: 15871.9 | D19: 8909.84 | E19: 82 | F19: 6962.06 | G19: 19 | H19: 9733 | I19: 5406.44 | J19: 36 | K19: 4326.56 | L19: 10 | M19: 25604.9 | N19: 14316.28 | O19: 118 | P19: 11288.62 | Q19: 29
B20: Oct | C20: 12267.4 | D20: 8504.58 | E20: 115 | F20: 3762.82 | G20: 24 | H20: 10162.65 | I20: 7280.39 | J20: 85 | K20: 2882.26 | L20: 21 | M20: 22430.05 | N20: 15784.97 | O20: 200 | P20: 6645.08 | Q20: 45
B21: Nov | C21: 29592.4 | D21: 19748 | E21: 113 | F21: 9844.4 | G21: 21 | H21: 14026.55 | I21: 8692.33 | J21: 76 | K21: 5334.22 | L21: 16 | M21: 43618.95 | N21: 28440.33 | O21: 189 | P21: 15178.62 | Q21: 37
B22: Dec | C22: 26586.2 | D22: 19349.24 | E22: 111 | F22: 7236.96 | G22: 23 | H22: 16261.65 | I22: 11962.96 | J22: 111 | K22: 4298.69 | L22: 22 | M22: 42847.85 | N22: 31312.2 | O22: 222 | P22: 11535.65 | Q22: 45
B23: Grand Total | C23: 213325.15 | D23: 137953.38 | E23: 1052 | F23: 75371.77 | G23: 246 | H23: 188339.45 | I23: 119543.43 | J23: 1051 | K23: 68796.02 | L23: 254 | M23: 401664.6 | N23: 257496.81 | O23: 2103 | P23: 144167.79 | Q23: 500
B27: Row Labels | C27: Sum of Revenue | D27: Sum of Profit | E27: Sum of Sales_Target | F27: Sum of Expenses | G27: Sum of Quantity
B28: Jan | C28: 31876.15 | D28: 10643.66 | E28: 32308 | F28: 21232.49 | G28: 172
B29: Feb | C29: 46454.8 | D29: 19235.1 | E29: 43973 | F29: 27219.7 | G29: 199
B30: Mar | C30: 25206.7 | D30: 9731.26 | E30: 27964 | F30: 15475.44 | G30: 158
B31: Apr | C31: 32333.95 | D31: 14386.62 | E31: 31226 | F31: 17947.33 | G31: 155
B32: May | C32: 29518.1 | D32: 9729.07 | E32: 29988 | F32: 19789.03 | G32: 168
B33: Jun | C33: 23538.6 | D33: 9734.61 | E33: 22413 | F33: 13803.99 | G33: 125
B34: Jul | C34: 42508.45 | D34: 14599.38 | E34: 47522 | F34: 27909.07 | G34: 195
B35: Aug | C35: 35726.1 | D35: 11460.12 | E35: 34529 | F35: 24265.98 | G35: 202
B36: Sep | C36: 25604.9 | D36: 11288.62 | E36: 29035 | F36: 14316.28 | G36: 118
B37: Oct | C37: 22430.05 | D37: 6645.08 | E37: 19967 | F37: 15784.97 | G37: 200
B38: Nov | C38: 43618.95 | D38: 15178.62 | E38: 44484 | F38: 28440.33 | G38: 189
B39: Dec | C39: 42847.85 | D39: 11535.65 | E39: 38871 | F39: 31312.2 | G39: 222
B40: Grand Total | C40: 401664.6 | D40: 144167.79 | E40: 402280 | F40: 257496.81 | G40: 2103
B44: Row Labels | C44: Sum of Revenue | D44: Sum of Profit | E44: Sum of Sales_Target | F44: Sum of Expenses | G44: Sum of Quantity
B45: Jan | C45: 31876.15 | D45: 10643.66 | E45: 32308 | F45: 21232.49 | G45: 172
B46: Feb | C46: 46454.8 | D46: 19235.1 | E46: 43973 | F46: 27219.7 | G46: 199
B47: Mar | C47: 25206.7 | D47: 9731.26 | E47: 27964 | F47: 15475.44 | G47: 158
B48: Apr | C48: 32333.95 | D48: 14386.62 | E48: 31226 | F48: 17947.33 | G48: 155
B49: May | C49: 29518.1 | D49: 9729.07 | E49: 29988 | F49: 19789.03 | G49: 168
B50: Jun | C50: 23538.6 | D50: 9734.61 | E50: 22413 | F50: 13803.99 | G50: 125
B51: Jul | C51: 42508.45 | D51: 14599.38 | E51: 47522 | F51: 27909.07 | G51: 195
...

Sheet Processing
B1: Total Revenue | C1: Total Expenses | D1: Total Quantity | E1: Total Profit | F1: Avg Order Value
B2: =GETPIVOTDATA("Sum of Revenue",Pivot!$B$4) -> 401664.6 | C2: =GETPIVOTDATA("Sum of Expenses",Pivot!$B$4) -> 257496.81 | D2: =GETPIVOTDATA("Sum of Quantity",Pivot!$B$4) -> 2103 | E2: =GETPIVOTDATA("Sum of Profit",Pivot!$B$4) -> 144167.79 | F2: =B2/GETPIVOTDATA("Count of Order_ID",Pivot!$B$4) -> 803.3292
B4: Renvenue 2024 | C4: Expenses 2024 | D4: Quantity 2024 | E4: Profit 2024
B5: =GETPIVOTDATA("Sum of Revenue",Pivot!$B$8,"Years (Order_Date)",2024) -> 188339.45 | C5: =GETPIVOTDATA("Sum of Expenses",Pivot!$B$8,"Years (Order_Date)",2024) -> 119543.43 | D5: =GETPIVOTDATA("Sum of Quantity",Pivot!$B$8,"Years (Order_Date)",2024) -> 1051 | E5: =GETPIVOTDATA("Sum of Profit",Pivot!$B$8,"Years (Order_Date)",2024) -> 68796.02
B7: Renvenue 2025 | C7: Expenses 2025 | D7: Quantity 2025 | E7: Profit 2025 | G7: [>=1000000]$0.00,,"M";[>=1000]$0.00,"K";0.00
B8: =GETPIVOTDATA("Sum of Revenue",Pivot!$B$8,"Years (Order_Date)",2025) -> 213325.15 | C8: =GETPIVOTDATA("Sum of Expenses",Pivot!$B$8,"Years (Order_Date)",2025) -> 137953.38 | D8: =GETPIVOTDATA("Sum of Quantity",Pivot!$B$8,"Years (Order_Date)",2025) -> 1052 | E8: =GETPIVOTDATA("Sum of Profit",Pivot!$B$8,"Years (Order_Date)",2025) -> 75371.77
B10: YoY Growth | C10: YoY Growth | D10: YoY Growth | E10: YoY Growth
B11: =(B8-B5)/B5 -> 0.13266313 | C11: =(C8-C5)/C5 -> 0.15400219 | D11: =(D8-D5)/D5 -> 0.00095147479 | E11: =(E8-E5)/E5 -> 0.095583291
A13: Positive | B13: =IF(B11>0,B11,"") -> 0.13266313 | C13: =IF(C11>0,C11,"") -> 0.15400219 | D13: =IF(D11>0,D11,"") -> 0.00095147479 | E13: =IF(E11>0,E11,"") -> 0.095583291
A14: Negative | B14: =IF(B11<0,B11,"") | C14: =IF(C11<0,C11,"") | D14: =IF(D11<0,D11,"") | E14: =IF(E11<0,E11,"")
D16: =MAX(B18:B29)*5% -> 961.755
A17: Monthly Profit Trends | B17: Profit | C17: Cursor P | D17: Cusor Indent
A18: Jan | B18: =GETPIVOTDATA("Sum of Profit",Pivot!$B$44,"Months (Order_Date)",A18) -> 10643.66 | C18: =IFERROR(GETPIVOTDATA("Sum of Profit",Pivot!$B$27,"Months (Order_Date)",A18),NA()) -> 10643.66 | D18: =IF(ISNUMBER(C18),$D$16,NA()) -> 961.755
A19: Feb | B19: =GETPIVOTDATA("Sum of Profit",Pivot!$B$44,"Months (Order_Date)",A19) -> 19235.1 | C19: =IFERROR(GETPIVOTDATA("Sum of Profit",Pivot!$B$27,"Months (Order_Date)",A19),NA()) -> 19235.1 | D19: =IF(ISNUMBER(C19),$D$16,NA()) -> 961.755
A20: Mar | B20: =GETPIVOTDATA("Sum of Profit",Pivot!$B$44,"Months (Order_Date)",A20) -> 9731.26 | C20: =IFERROR(GETPIVOTDATA("Sum of Profit",Pivot!$B$27,"Months (Order_Date)",A20),NA()) -> 9731.26 | D20: =IF(ISNUMBER(C20),$D$16,NA()) -> 961.755
A21: Apr | B21: =GETPIVOTDATA("Sum of Profit",Pivot!$B$44,"Months (Order_Date)",A21) -> 14386.62 | C21: =IFERROR(GETPIVOTDATA("Sum of Profit",Pivot!$B$27,"Months (Order_Date)",A21),NA()) -> 14386.62 | D21: =IF(ISNUMBER(C21),$D$16,NA()) -> 961.755
A22: May | B22: =GETPIVOTDATA("Sum of Profit",Pivot!$B$44,"Months (Order_Date)",A22) -> 9729.07 | C22: =IFERROR(GETPIVOTDATA("Sum of Profit",Pivot!$B$27,"Months (Order_Date)",A22),NA()) -> 9729.07 | D22: =IF(ISNUMBER(C22),$D$16,NA()) -> 961.755
A23: Jun | B23: =GETPIVOTDATA("Sum of Profit",Pivot!$B$44,"Months (Order_Date)",A23) -> 9734.61 | C23: =IFERROR(GETPIVOTDATA("Sum of Profit",Pivot!$B$27,"Months (Order_Date)",A23),NA()) -> 9734.61 | D23: =IF(ISNUMBER(C23),$D$16,NA()) -> 961.755
A24: Jul | B24: =GETPIVOTDATA("Sum of Profit",Pivot!$B$44,"Months (Order_Date)",A24) -> 14599.38 | C24: =IFERROR(GETPIVOTDATA("Sum of Profit",Pivot!$B$27,"Months (Order_Date)",A24),NA()) -> 14599.38 | D24: =IF(ISNUMBER(C24),$D$16,NA()) -> 961.755
A25: Aug | B25: =GETPIVOTDATA("Sum of Profit",Pivot!$B$44,"Months (Order_Date)",A25) -> 11460.12 | C25: =IFERROR(GETPIVOTDATA("Sum of Profit",Pivot!$B$27,"Months (Order_Date)",A25),NA()) -> 11460.12 | D25: =IF(ISNUMBER(C25),$D$16,NA()) -> 961.755
A26: Sep | B26: =GETPIVOTDATA("Sum of Profit",Pivot!$B$44,"Months (Order_Date)",A26) -> 11288.62 | C26: =IFERROR(GETPIVOTDATA("Sum of Profit",Pivot!$B$27,"Months (Order_Date)",A26),NA()) -> 11288.62 | D26: =IF(ISNUMBER(C26),$D$16,NA()) -> 961.755
A27: Oct | B27: =GETPIVOTDATA("Sum of Profit",Pivot!$B$44,"Months (Order_Date)",A27) -> 6645.08 | C27: =IFERROR(GETPIVOTDATA("Sum of Profit",Pivot!$B$27,"Months (Order_Date)",A27),NA()) -> 6645.08 | D27: =IF(ISNUMBER(C27),$D$16,NA()) -> 961.755
A28: Nov | B28: =GETPIVOTDATA("Sum of Profit",Pivot!$B$44,"Months (Order_Date)",A28) -> 15178.62 | C28: =IFERROR(GETPIVOTDATA("Sum of Profit",Pivot!$B$27,"Months (Order_Date)",A28),NA()) -> 15178.62 | D28: =IF(ISNUMBER(C28),$D$16,NA()) -> 961.755
A29: Dec | B29: =GETPIVOTDATA("Sum of Profit",Pivot!$B$44,"Months (Order_Date)",A29) -> 11535.65 | C29: =IFERROR(GETPIVOTDATA("Sum of Profit",Pivot!$B$27,"Months (Order_Date)",A29),NA()) -> 11535.65 | D29: =IF(ISNUMBER(C29),$D$16,NA()) -> 961.755
C30: =SUMIF(C18:C29,">0") -> 144167.79
A32: Monthly Revenue Trends | D32: FALSE
A33: Month | B33: Sales | C33: Sales Plan | D33: Line Plan | E33: padding | F33: Cursor | G33: Marker
A34: JAN | B34: =GETPIVOTDATA("Sum of Revenue",Pivot!$B$44,"Months (Order_Date)",A34) -> 31876.15 | C34: =GETPIVOTDATA("Sum of Sales_Target",Pivot!$B$44,"Months (Order_Date)",A34) -> 32308 | D34: =IF($D$32,IFERROR(GETPIVOTDATA("Sum of Sales_Target",Pivot!$B$44,"Months (Order_Date)",A34),NA()),NA()) -> #N/A | E34: -3000 | F34: =IFERROR(GETPIVOTDATA("Sum of Revenue",Pivot!$B$27,"Months (Order_Date)",A34)+MAX($B$34:$B$45)*$F$46,NA()) -> 38844.37 | G34: =IFERROR(GETPIVOTDATA("Sum of Revenue",Pivot!$B$27,"Months (Order_Date)",A34),NA()) -> 31876.15 | H34: Switch
A35: FEB | B35: =GETPIVOTDATA("Sum of Revenue",Pivot!$B$44,"Months (Order_Date)",A35) -> 46454.8 | C35: =GETPIVOTDATA("Sum of Sales_Target",Pivot!$B$44,"Months (Order_Date)",A35) -> 43973 | D35: =IF($D$32,IFERROR(GETPIVOTDATA("Sum of Sales_Target",Pivot!$B$44,"Months (Order_Date)",A35),NA()),NA()) -> #N/A | E35: -3000 | F35: =IFERROR(GETPIVOTDATA("Sum of Revenue",Pivot!$B$27,"Months (Order_Date)",A35)+MAX($B$34:$B$45)*$F$46,NA()) -> 53423.02 | G35: =IFERROR(GETPIVOTDATA("Sum of Revenue",Pivot!$B$27,"Months (Order_Date)",A35),NA()) -> 46454.8 | H35: =IF(D32,0,1) -> 1 | I35: =IF(D32,1,0)
A36: MAR | B36: =GETPIVOTDATA("Sum of Revenue",Pivot!$B$44,"Months (Order_Date)",A36) -> 25206.7 | C36: =GETPIVOTDATA("Sum of Sales_Target",Pivot!$B$44,"Months (Order_Date)",A36) -> 27964 | D36: =IF($D$32,IFERROR(GETPIVOTDATA("Sum of Sales_Target",Pivot!$B$44,"Months (Order_Date)",A36),NA()),NA()) -> #N/A | E36: -3000 | F36: =IFERROR(GETPIVOTDATA("Sum of Revenue",Pivot!$B$27,"Months (Order_Date)",A36)+MAX($B$34:$B$45)*$F$46,NA()) -> 32174.92 | G36: =IFERROR(GETPIVOTDATA("Sum of Revenue",Pivot!$B$27,"Months (Order_Date)",A36),NA()) -> 25206.7 | H36: =IF(D32,1,0) -> 0
A37: APR | B37: =GETPIVOTDATA("Sum of Revenue",Pivot!$B$44,"Months (Order_Date)",A37) -> 32333.95 | C37: =GETPIVOTDATA("Sum of Sales_Target",Pivot!$B$44,"Months (Order_Date)",A37) -> 31226 | D37: =IF($D$32,IFERROR(GETPIVOTDATA("Sum of Sales_Target",Pivot!$B$44,"Months (Order_Date)",A37),NA()),NA()) -> #N/A | E37: -3000 | F37: =IFERROR(GETPIVOTDATA("Sum of Revenue",Pivot!$B$27,"Months (Order_Date)",A37)+MAX($B$34:$B$45)*$F$46,NA()) -> 39302.17 | G37: =IFERROR(GETPIVOTDATA("Sum of Revenue",Pivot!$B$27,"Months (Order_Date)",A37),NA()) -> 32333.95
A38: MAY | B38: =GETPIVOTDATA("Sum of Revenue",Pivot!$B$44,"Months (Order_Date)",A38) -> 29518.1 | C38: =GETPIVOTDATA("Sum of Sales_Target",Pivot!$B$44,"Months (Order_Date)",A38) -> 29988 | D38: =IF($D$32,IFERROR(GETPIVOTDATA("Sum of Sales_Target",Pivot!$B$44,"Months (Order_Date)",A38),NA()),NA()) -> #N/A | E38: -3000 | F38: =IFERROR(GETPIVOTDATA("Sum of Revenue",Pivot!$B$27,"Months (Order_Date)",A38)+MAX($B$34:$B$45)*$F$46,NA()) -> 36486.32 | G38: =IFERROR(GETPIVOTDATA("Sum of Revenue",Pivot!$B$27,"Months (Order_Date)",A38),NA()) -> 29518.1
A39: JUN | B39: =GETPIVOTDATA("Sum of Revenue",Pivot!$B$44,"Months (Order_Date)",A39) -> 23538.6 | C39: =GETPIVOTDATA("Sum of Sales_Target",Pivot!$B$44,"Months (Order_Date)",A39) -> 22413 | D39: =IF($D$32,IFERROR(GETPIVOTDATA("Sum of Sales_Target",Pivot!$B$44,"Months (Order_Date)",A39),NA()),NA()) -> #N/A | E39: -3000 | F39: =IFERROR(GETPIVOTDATA("Sum of Revenue",Pivot!$B$27,"Months (Order_Date)",A39)+MAX($B$34:$B$45)*$F$46,NA()) -> 30506.82 | G39: =IFERROR(GETPIVOTDATA("Sum of Revenue",Pivot!$B$27,"Months (Order_Date)",A39),NA()) -> 23538.6
A40: JUL | B40: =GETPIVOTDATA("Sum of Revenue",Pivot!$B$44,"Months (Order_Date)",A40) -> 42508.45 | C40: =GETPIVOTDATA("Sum of Sales_Target",Pivot!$B$44,"Months (Order_Date)",A40) -> 47522 | D40: =IF($D$32,IFERROR(GETPIVOTDATA("Sum of Sales_Target",Pivot!$B$44,"Months (Order_Date)",A40),NA()),NA()) -> #N/A | E40: -3000 | F40: =IFERROR(GETPIVOTDATA("Sum of Revenue",Pivot!$B$27,"Months (Order_Date)",A40)+MAX($B$34:$B$45)*$F$46,NA()) -> 49476.67 | G40: =IFERROR(GETPIVOTDATA("Sum of Revenue",Pivot!$B$27,"Months (Order_Date)",A40),NA()) -> 42508.45
A41: AUG | B41: =GETPIVOTDATA("Sum of Revenue",Pivot!$B$44,"Months (Order_Date)",A41) -> 35726.1 | C41: =GETPIVOTDATA("Sum of Sales_Target",Pivot!$B$44,"Months (Order_Date)",A41) -> 34529 | D41: =IF($D$32,IFERROR(GETPIVOTDATA("Sum of Sales_Target",Pivot!$B$44,"Months (Order_Date)",A41),NA()),NA()) -> #N/A | E41: -3000 | F41: =IFERROR(GETPIVOTDATA("Sum of Revenue",Pivot!$B$27,"Months (Order_Date)",A41)+MAX($B$34:$B$45)*$F$46,NA()) -> 42694.32 | G41: =IFERROR(GETPIVOTDATA("Sum of Revenue",Pivot!$B$27,"Months (Order_Date)",A41),NA()) -> 35726.1
A42: SEP | B42: =GETPIVOTDATA("Sum of Revenue",Pivot!$B$44,"Months (Order_Date)",A42) -> 25604.9 | C42: =GETPIVOTDATA("Sum of Sales_Target",Pivot!$B$44,"Months (Order_Date)",A42) -> 29035 | D42: =IF($D$32,IFERROR(GETPIVOTDATA("Sum of Sales_Target",Pivot!$B$44,"Months (Order_Date)",A42),NA()),NA()) -> #N/A | E42: -3000 | F42: =IFERROR(GETPIVOTDATA("Sum of Revenue",Pivot!$B$27,"Months (Order_Date)",A42)+MAX($B$34:$B$45)*$F$46,NA()) -> 32573.12 | G42: =IFERROR(GETPIVOTDATA("Sum of Revenue",Pivot!$B$27,"Months (Order_Date)",A42),NA()) -> 25604.9
A43: OCT | B43: =GETPIVOTDATA("Sum of Revenue",Pivot!$B$44,"Months (Order_Date)",A43) -> 22430.05 | C43: =GETPIVOTDATA("Sum of Sales_Target",Pivot!$B$44,"Months (Order_Date)",A43) -> 19967 | D43: =IF($D$32,IFERROR(GETPIVOTDATA("Sum of Sales_Target",Pivot!$B$44,"Months (Order_Date)",A43),NA()),NA()) -> #N/A | E43: -3000 | F43: =IFERROR(GETPIVOTDATA("Sum of Revenue",Pivot!$B$27,"Months (Order_Date)",A43)+MAX($B$34:$B$45)*$F$46,NA()) -> 29398.27 | G43: =IFERROR(GETPIVOTDATA("Sum of Revenue",Pivot!$B$27,"Months (Order_Date)",A43),NA()) -> 22430.05
A44: NOV | B44: =GETPIVOTDATA("Sum of Revenue",Pivot!$B$44,"Months (Order_Date)",A44) -> 43618.95 | C44: =GETPIVOTDATA("Sum of Sales_Target",Pivot!$B$44,"Months (Order_Date)",A44) -> 44484 | D44: =IF($D$32,IFERROR(GETPIVOTDATA("Sum of Sales_Target",Pivot!$B$44,"Months (Order_Date)",A44),NA()),NA()) -> #N/A | E44: -3000 | F44: =IFERROR(GETPIVOTDATA("Sum of Revenue",Pivot!$B$27,"Months (Order_Date)",A44)+MAX($B$34:$B$45)*$F$46,NA()) -> 50587.17 | G44: =IFERROR(GETPIVOTDATA("Sum of Revenue",Pivot!$B$27,"Months (Order_Date)",A44),NA()) -> 43618.95
A45: DEC | B45: =GETPIVOTDATA("Sum of Revenue",Pivot!$B$44,"Months (Order_Date)",A45) -> 42847.85 | C45: =GETPIVOTDATA("Sum of Sales_Target",Pivot!$B$44,"Months (Order_Date)",A45) -> 38871 | D45: =IF($D$32,IFERROR(GETPIVOTDATA("Sum of Sales_Target",Pivot!$B$44,"Months (Order_Date)",A45),NA()),NA()) -> #N/A | E45: -3000 | F45: =IFERROR(GETPIVOTDATA("Sum of Revenue",Pivot!$B$27,"Months (Order_Date)",A45)+MAX($B$34:$B$45)*$F$46,NA()) -> 49816.07 | G45: =IFERROR(GETPIVOTDATA("Sum of Revenue",Pivot!$B$27,"Months (Order_Date)",A45),NA()) -> 42847.85
B46: =GETPIVOTDATA("Sum of Revenue",Pivot!$B$27) -> 401664.6 | C46: =GETPIVOTDATA("Sum of Sales_Target",Pivot!$B$27) -> 402280 | F46: 0.15
...

Sheet Dashboard

Sheet Profitability

Sheet Operations

Sheet Dataset
B6: Order_ID | C6: Order_Date | D6: City | E6: Region | F6: Category | G6: Sub_Category | H6: Department | I6: Customer_Type | J6: Order_Priority | K6: Quantity | L6: Unit_Price | M6: Discount_% | N6: Gross_Sales | O6: Revenue | P6: Expenses | Q6: Profit | R6: Profit_Margin_% | S6: Expense_Ratio_% | T6: Sales_Target | U6: Target_Achievement_% | V6: Return_Qty | W6: Return_Rate_%
B7: ORD-00001 | C7: 45550 | D7: Phoenix | E7: West | F7: Accessories | G7: Bags | H7: Corporate | I7: Returning | J7: Standard | K7: 4 | L7: 300 | M7: 0.03 | N7: 1200 | O7: 1164 | P7: 601.82 | Q7: 562.18 | R7: 0.483 | S7: 0.517 | T7: 876 | U7: 1.7321 | V7: 1 | W7: 0.25
B8: ORD-00002 | C8: 45409 | D8: Los Angeles | E8: West | F8: Technology | G8: Kitchen | H8: Retail | I8: Returning | J8: Standard | K8: 5 | L8: 25 | M8: 0.15 | N8: 125 | O8: 106.25 | P8: 71.94 | Q8: 34.31 | R8: 0.3229 | S8: 0.6771 | T8: 63 | U8: 0.1124 | V8: 0 | W8: 0
B9: ORD-00003 | C9: 45999 | D9: New York | E9: Northeast | F9: Technology | G9: Chairs | H9: Retail | I9: Returning | J9: Standard | K9: 4 | L9: 200 | M9: 0.08 | N9: 800 | O9: 736 | P9: 548.02 | Q9: 187.98 | R9: 0.2554 | S9: 0.7446 | T9: 587 | U9: 0.6815 | V9: 0 | W9: 0
B10: ORD-00004 | C10: 45542 | D10: Los Angeles | E10: West | F10: Office Supplies | G10: Bags | H10: Corporate | I10: Returning | J10: Standard | K10: 5 | L10: 150 | M10: 0 | N10: 750 | O10: 750 | P10: 431.08 | Q10: 318.92 | R10: 0.4252 | S10: 0.5748 | T10: 907 | U10: 1.0302 | V10: 0 | W10: 0
B11: ORD-00005 | C11: 45913 | D11: Los Angeles | E11: West | F11: Office Supplies | G11: Laptops | H11: Corporate | I11: Returning | J11: Express | K11: 5 | L11: 40 | M11: 0 | N11: 200 | O11: 200 | P11: 105.1 | Q11: 94.9 | R11: 0.4745 | S11: 0.5255 | T11: 205 | U11: 0.2747 | V11: 1 | W11: 0.2
B12: ORD-00006 | C12: 45972 | D12: Miami | E12: South | F12: Appliances | G12: Kitchen | H12: Retail | I12: New | J12: Standard | K12: 5 | L12: 750 | M12: 0.1 | N12: 3750 | O12: 3375 | P12: 2508.73 | Q12: 866.27 | R12: 0.2567 | S12: 0.7433 | T12: 2279 | U12: 3.5156 | V12: 1 | W12: 0.2
B13: ORD-00007 | C13: 45422 | D13: Houston | E13: South | F13: Furniture | G13: Bags | H13: Consumer | I13: Returning | J13: Standard | K13: 2 | L13: 500 | M13: 0.05 | N13: 1000 | O13: 950 | P13: 590.03 | Q13: 359.97 | R13: 0.3789 | S13: 0.6211 | T13: 1032 | U13: 1.2056 | V13: 0 | W13: 0
B14: ORD-00008 | C14: 45361 | D14: Miami | E14: South | F14: Appliances | G14: Phones | H14: Consumer | I14: New | J14: Standard | K14: 6 | L14: 60 | M14: 0.05 | N14: 360 | O14: 342 | P14: 226.89 | Q14: 115.11 | R14: 0.3366 | S14: 0.6634 | T14: 372 | U14: 0.4275 | V14: 1 | W14: 0.1667
B15: ORD-00009 | C15: 45521 | D15: New York | E15: Northeast | F15: Office Supplies | G15: Laptops | H15: Enterprise | I15: New | J15: Standard | K15: 3 | L15: 60 | M15: 0.1 | N15: 180 | O15: 162 | P15: 107.92 | Q15: 54.08 | R15: 0.3338 | S15: 0.6662 | T15: 173 | U15: 0.2225 | V15: 0 | W15: 0
B16: ORD-00010 | C16: 45882 | D16: Phoenix | E16: West | F16: Office Supplies | G16: Phones | H16: Enterprise | I16: Returning | J16: Express | K16: 4 | L16: 100 | M16: 0.15 | N16: 400 | O16: 340 | P16: 235.85 | Q16: 104.15 | R16: 0.3063 | S16: 0.6937 | T16: 365 | U16: 0.467 | V16: 0 | W16: 0
B17: ORD-00011 | C17: 45848 | D17: Los Angeles | E17: West | F17: Accessories | G17: Laptops | H17: Retail | I17: Returning | J17: Standard | K17: 5 | L17: 750 | M17: 0 | N17: 3750 | O17: 3750 | P17: 2617.46 | Q17: 1132.54 | R17: 0.302 | S17: 0.698 | T17: 1731 | U17: 5.5804 | V17: 0 | W17: 0
B18: ORD-00012 | C18: 45786 | D18: Miami | E18: South | F18: Office Supplies | G18: Kitchen | H18: Consumer | I18: New | J18: Standard | K18: 1 | L18: 25 | M18: 0.08 | N18: 25 | O18: 23 | P18: 15.33 | Q18: 7.67 | R18: 0.3335 | S18: 0.6665 | T18: 25 | U18: 0.0337 | V18: 0 | W18: 0
... B506: ORD-00500 | C506: 45849 | D506: New York | E506: Northeast | F506: Accessories | G506: Kitchen | H506: Corporate | I506: Returning | J506: Standard | K506: 1 | L506: 60 | M506: 0 | N506: 60 | O506: 60 | P506: 43.39 | Q506: 16.61 | R506: 0.2768 | S506: 0.7232 | T506: 672 | U506: 0.0893 | V506: 0 | W506: 0

Sheet Insights

Sheet Feuil1
